
[2021-04-09 14:04:06] Traceback (most recent call last):
  File "v8function_handler.pyx", line 48, in cefpython_py37.V8FunctionHandler_Execute
  File "/media/feodoritiy/HDD/CODE/VS_C+/fti/Cursach/client/logic/register.py", line 16, in register
    res = json.loads(res.text)
  File "/usr/lib/python3.7/json/__init__.py", line 348, in loads
    return _default_decoder.decode(s)
  File "/usr/lib/python3.7/json/decoder.py", line 337, in decode
    obj, end = self.raw_decode(s, idx=_w(s, 0).end())
  File "/usr/lib/python3.7/json/decoder.py", line 355, in raw_decode
    raise JSONDecodeError("Expecting value", s, err.value) from None
json.decoder.JSONDecodeError: Expecting value: line 1 column 1 (char 0)


[2021-04-09 23:53:30] Traceback (most recent call last):
  File "v8function_handler.pyx", line 48, in cefpython_py37.V8FunctionHandler_Execute
  File "/media/feodoritiy/HDD/CODE/VS_C+/fti/Cursach/client/logic/register.py", line 19, in register
    return res.status
AttributeError: 'dict' object has no attribute 'status'


[2021-04-10 00:50:28] Traceback (most recent call last):
  File "v8function_handler.pyx", line 48, in cefpython_py37.V8FunctionHandler_Execute
  File "/media/feodoritiy/HDD/CODE/VS_C+/fti/Cursach/client/logic/register.py", line 21, in register
    storage.id = res['id']
NameError: name 'storage' is not defined


[2021-04-10 01:29:01] Traceback (most recent call last):
  File "v8function_handler.pyx", line 48, in cefpython_py37.V8FunctionHandler_Execute
  File "/media/feodoritiy/HDD/CODE/VS_C+/fti/Cursach/client/logic/login.py", line 17, in login
    res = json.loads(res.text)
  File "/usr/lib/python3.7/json/__init__.py", line 348, in loads
    return _default_decoder.decode(s)
  File "/usr/lib/python3.7/json/decoder.py", line 337, in decode
    obj, end = self.raw_decode(s, idx=_w(s, 0).end())
  File "/usr/lib/python3.7/json/decoder.py", line 355, in raw_decode
    raise JSONDecodeError("Expecting value", s, err.value) from None
json.decoder.JSONDecodeError: Expecting value: line 1 column 1 (char 0)


[2021-04-10 01:30:08] Traceback (most recent call last):
  File "v8function_handler.pyx", line 48, in cefpython_py37.V8FunctionHandler_Execute
  File "/media/feodoritiy/HDD/CODE/VS_C+/fti/Cursach/client/logic/login.py", line 17, in login
    res = json.loads(res.text)
  File "/usr/lib/python3.7/json/__init__.py", line 348, in loads
    return _default_decoder.decode(s)
  File "/usr/lib/python3.7/json/decoder.py", line 337, in decode
    obj, end = self.raw_decode(s, idx=_w(s, 0).end())
  File "/usr/lib/python3.7/json/decoder.py", line 355, in raw_decode
    raise JSONDecodeError("Expecting value", s, err.value) from None
json.decoder.JSONDecodeError: Expecting value: line 1 column 1 (char 0)


[2021-04-10 01:32:01] Traceback (most recent call last):
  File "v8function_handler.pyx", line 48, in cefpython_py37.V8FunctionHandler_Execute
  File "/media/feodoritiy/HDD/CODE/VS_C+/fti/Cursach/client/logic/login.py", line 17, in login
    res = json.loads(res.text)
  File "/usr/lib/python3.7/json/__init__.py", line 348, in loads
    return _default_decoder.decode(s)
  File "/usr/lib/python3.7/json/decoder.py", line 337, in decode
    obj, end = self.raw_decode(s, idx=_w(s, 0).end())
  File "/usr/lib/python3.7/json/decoder.py", line 355, in raw_decode
    raise JSONDecodeError("Expecting value", s, err.value) from None
json.decoder.JSONDecodeError: Expecting value: line 1 column 1 (char 0)


[2021-04-10 01:33:08] Traceback (most recent call last):
  File "v8function_handler.pyx", line 48, in cefpython_py37.V8FunctionHandler_Execute
  File "/media/feodoritiy/HDD/CODE/VS_C+/fti/Cursach/client/logic/login.py", line 17, in login
    res = json.loads(res.text)
  File "/usr/lib/python3.7/json/__init__.py", line 348, in loads
    return _default_decoder.decode(s)
  File "/usr/lib/python3.7/json/decoder.py", line 337, in decode
    obj, end = self.raw_decode(s, idx=_w(s, 0).end())
  File "/usr/lib/python3.7/json/decoder.py", line 355, in raw_decode
    raise JSONDecodeError("Expecting value", s, err.value) from None
json.decoder.JSONDecodeError: Expecting value: line 1 column 1 (char 0)


[2021-04-10 01:34:28] Traceback (most recent call last):
  File "v8function_handler.pyx", line 48, in cefpython_py37.V8FunctionHandler_Execute
  File "/media/feodoritiy/HDD/CODE/VS_C+/fti/Cursach/client/logic/login.py", line 17, in login
    res = json.loads(res.text)
  File "/usr/lib/python3.7/json/__init__.py", line 348, in loads
    return _default_decoder.decode(s)
  File "/usr/lib/python3.7/json/decoder.py", line 337, in decode
    obj, end = self.raw_decode(s, idx=_w(s, 0).end())
  File "/usr/lib/python3.7/json/decoder.py", line 355, in raw_decode
    raise JSONDecodeError("Expecting value", s, err.value) from None
json.decoder.JSONDecodeError: Expecting value: line 1 column 1 (char 0)


[2021-04-11 23:10:19] Traceback (most recent call last):
  File "v8function_handler.pyx", line 48, in cefpython_py37.V8FunctionHandler_Execute
  File "/media/feodoritiy/HDD/CODE/VS_C+/fti/Cursach/client/logic/shop.py", line 20, in get_shop
    'id': storage.id,
TypeError: 'cefpython_py37.JavascriptCallback' object is not callable


[2021-04-12 00:29:32] Traceback (most recent call last):
  File "v8function_handler.pyx", line 48, in cefpython_py37.V8FunctionHandler_Execute
  File "/media/feodoritiy/HDD/CODE/VS_C+/fti/Cursach/client/logic/shop.py", line 22, in get_shop
    'shop': res.shop,
AttributeError: 'dict' object has no attribute 'shop'


[2021-04-12 21:55:41] Traceback (most recent call last):
  File "v8function_handler.pyx", line 48, in cefpython_py37.V8FunctionHandler_Execute
  File "/media/feodoritiy/HDD/CODE/VS_C+/fti/Cursach/client/logic/shop.py", line 19, in get_shop
    if (res['status'] == 'OK'):
TypeError: 'Response' object is not subscriptable


[2021-04-12 21:57:44] Traceback (most recent call last):
  File "v8function_handler.pyx", line 48, in cefpython_py37.V8FunctionHandler_Execute
  File "/media/feodoritiy/HDD/CODE/VS_C+/fti/Cursach/client/logic/shop.py", line 19, in get_shop
    if (res['status'] == 'OK'):
TypeError: 'Response' object is not subscriptable


[2021-04-12 22:02:02] Traceback (most recent call last):
  File "v8function_handler.pyx", line 48, in cefpython_py37.V8FunctionHandler_Execute
  File "/media/feodoritiy/HDD/CODE/VS_C+/fti/Cursach/client/logic/shop.py", line 19, in get_shop
    if (res['status'] == 'OK'):
TypeError: 'Response' object is not subscriptable


[2021-04-12 22:04:24] Traceback (most recent call last):
  File "v8function_handler.pyx", line 48, in cefpython_py37.V8FunctionHandler_Execute
  File "/media/feodoritiy/HDD/CODE/VS_C+/fti/Cursach/client/logic/shop.py", line 19, in get_shop
    if (res['status'] == 'OK'):
TypeError: 'Response' object is not subscriptable


[2021-04-12 22:45:10] Traceback (most recent call last):
  File "v8function_handler.pyx", line 48, in cefpython_py37.V8FunctionHandler_Execute
  File "/media/feodoritiy/HDD/CODE/VS_C+/fti/Cursach/client/logic/shop.py", line 41, in shop_select
    if res['status'] == 'OK':
TypeError: 'Response' object is not subscriptable


[2021-04-12 23:05:17] Traceback (most recent call last):
  File "v8function_handler.pyx", line 48, in cefpython_py37.V8FunctionHandler_Execute
  File "/media/feodoritiy/HDD/CODE/VS_C+/fti/Cursach/client/logic/shop.py", line 41, in shop_select
    if res['status'] == 'OK':
TypeError: 'Response' object is not subscriptable


[2021-04-12 23:06:47] Traceback (most recent call last):
  File "v8function_handler.pyx", line 48, in cefpython_py37.V8FunctionHandler_Execute
  File "/media/feodoritiy/HDD/CODE/VS_C+/fti/Cursach/client/logic/shop.py", line 41, in shop_select
    if res['status'] == 'OK':
TypeError: 'Response' object is not subscriptable


[2021-04-14 00:20:35] Traceback (most recent call last):
  File "/usr/lib/python3/dist-packages/urllib3/connection.py", line 160, in _new_conn
    (self._dns_host, self.port), self.timeout, **extra_kw
  File "/usr/lib/python3/dist-packages/urllib3/util/connection.py", line 84, in create_connection
    raise err
  File "/usr/lib/python3/dist-packages/urllib3/util/connection.py", line 74, in create_connection
    sock.connect(sa)
ConnectionRefusedError: [Errno 111] Connection refused

During handling of the above exception, another exception occurred:

Traceback (most recent call last):
  File "/usr/lib/python3/dist-packages/urllib3/connectionpool.py", line 672, in urlopen
    chunked=chunked,
  File "/usr/lib/python3/dist-packages/urllib3/connectionpool.py", line 387, in _make_request
    conn.request(method, url, **httplib_request_kw)
  File "/usr/lib/python3.7/http/client.py", line 1277, in request
    self._send_request(method, url, body, headers, encode_chunked)
  File "/usr/lib/python3.7/http/client.py", line 1323, in _send_request
    self.endheaders(body, encode_chunked=encode_chunked)
  File "/usr/lib/python3.7/http/client.py", line 1272, in endheaders
    self._send_output(message_body, encode_chunked=encode_chunked)
  File "/usr/lib/python3.7/http/client.py", line 1032, in _send_output
    self.send(msg)
  File "/usr/lib/python3.7/http/client.py", line 972, in send
    self.connect()
  File "/usr/lib/python3/dist-packages/urllib3/connection.py", line 187, in connect
    conn = self._new_conn()
  File "/usr/lib/python3/dist-packages/urllib3/connection.py", line 172, in _new_conn
    self, "Failed to establish a new connection: %s" % e
urllib3.exceptions.NewConnectionError: <urllib3.connection.HTTPConnection object at 0x7f3b48e4d5d0>: Failed to establish a new connection: [Errno 111] Connection refused

During handling of the above exception, another exception occurred:

Traceback (most recent call last):
  File "/usr/lib/python3/dist-packages/requests/adapters.py", line 449, in send
    timeout=timeout
  File "/usr/lib/python3/dist-packages/urllib3/connectionpool.py", line 720, in urlopen
    method, url, error=e, _pool=self, _stacktrace=sys.exc_info()[2]
  File "/usr/lib/python3/dist-packages/urllib3/util/retry.py", line 436, in increment
    raise MaxRetryError(_pool, url, error or ResponseError(cause))
urllib3.exceptions.MaxRetryError: HTTPConnectionPool(host='127.0.0.1', port=1234): Max retries exceeded with url: /login (Caused by NewConnectionError('<urllib3.connection.HTTPConnection object at 0x7f3b48e4d5d0>: Failed to establish a new connection: [Errno 111] Connection refused'))

During handling of the above exception, another exception occurred:

Traceback (most recent call last):
  File "v8function_handler.pyx", line 48, in cefpython_py37.V8FunctionHandler_Execute
  File "/media/feodoritiy/HDD/CODE/VS_C+/fti/Cursach/client/logic/login.py", line 10, in login
    'password': password,
  File "/media/feodoritiy/HDD/CODE/VS_C+/fti/Cursach/client/storage.py", line 19, in load
    res = requests.post(f'{SERVER}{path}', data)
  File "/usr/lib/python3/dist-packages/requests/api.py", line 116, in post
    return request('post', url, data=data, json=json, **kwargs)
  File "/usr/lib/python3/dist-packages/requests/api.py", line 60, in request
    return session.request(method=method, url=url, **kwargs)
  File "/usr/lib/python3/dist-packages/requests/sessions.py", line 533, in request
    resp = self.send(prep, **send_kwargs)
  File "/usr/lib/python3/dist-packages/requests/sessions.py", line 646, in send
    r = adapter.send(request, **kwargs)
  File "/usr/lib/python3/dist-packages/requests/adapters.py", line 516, in send
    raise ConnectionError(e, request=request)
requests.exceptions.ConnectionError: HTTPConnectionPool(host='127.0.0.1', port=1234): Max retries exceeded with url: /login (Caused by NewConnectionError('<urllib3.connection.HTTPConnection object at 0x7f3b48e4d5d0>: Failed to establish a new connection: [Errno 111] Connection refused'))


[2021-04-14 01:56:22] Traceback (most recent call last):
  File "/media/feodoritiy/HDD/CODE/VS_C+/fti/Cursach/client/storage.py", line 22, in load
    res = json.loads(res.text)
  File "/usr/lib/python3.7/json/__init__.py", line 348, in loads
    return _default_decoder.decode(s)
  File "/usr/lib/python3.7/json/decoder.py", line 337, in decode
    obj, end = self.raw_decode(s, idx=_w(s, 0).end())
  File "/usr/lib/python3.7/json/decoder.py", line 355, in raw_decode
    raise JSONDecodeError("Expecting value", s, err.value) from None
json.decoder.JSONDecodeError: Expecting value: line 1 column 1 (char 0)

During handling of the above exception, another exception occurred:

Traceback (most recent call last):
  File "v8function_handler.pyx", line 48, in cefpython_py37.V8FunctionHandler_Execute
  File "/media/feodoritiy/HDD/CODE/VS_C+/fti/Cursach/client/logic/create_game.py", line 7, in create_game
    id: storage.id,
  File "/media/feodoritiy/HDD/CODE/VS_C+/fti/Cursach/client/storage.py", line 24, in load
    print(f'''Error: parsing JSON on storage.load('{path}', '{json.dumps(data, indent=3)}').\nIncoming JSON:\n{res.text}''')
  File "/usr/lib/python3.7/json/__init__.py", line 238, in dumps
    **kw).encode(obj)
  File "/usr/lib/python3.7/json/encoder.py", line 201, in encode
    chunks = list(chunks)
  File "/usr/lib/python3.7/json/encoder.py", line 431, in _iterencode
    yield from _iterencode_dict(o, _current_indent_level)
  File "/usr/lib/python3.7/json/encoder.py", line 376, in _iterencode_dict
    raise TypeError(f'keys must be str, int, float, bool or None, '
TypeError: keys must be str, int, float, bool or None, not builtin_function_or_method


[2021-04-14 03:36:57] Traceback (most recent call last):
  File "v8function_handler.pyx", line 48, in cefpython_py37.V8FunctionHandler_Execute
  File "/media/feodoritiy/HDD/CODE/VS_C+/fti/Cursach/client/logic/create_game.py", line 16, in create_game
    storage.flask.run(host="127.0.0.1", port=1235, debug=True)
  File "/home/feodoritiy/.local/lib/python3.7/site-packages/flask/app.py", line 990, in run
    run_simple(host, port, self, **options)
  File "/home/feodoritiy/.local/lib/python3.7/site-packages/werkzeug/serving.py", line 1050, in run_simple
    run_with_reloader(inner, extra_files, reloader_interval, reloader_type)
  File "/home/feodoritiy/.local/lib/python3.7/site-packages/werkzeug/_reloader.py", line 339, in run_with_reloader
    sys.exit(reloader.restart_with_reloader())
SystemExit: 0


[2021-04-14 05:10:42] Traceback (most recent call last):
  File "/usr/lib/python3/dist-packages/urllib3/connectionpool.py", line 672, in urlopen
    chunked=chunked,
  File "/usr/lib/python3/dist-packages/urllib3/connectionpool.py", line 421, in _make_request
    six.raise_from(e, None)
  File "<string>", line 3, in raise_from
  File "/usr/lib/python3/dist-packages/urllib3/connectionpool.py", line 416, in _make_request
    httplib_response = conn.getresponse()
  File "/usr/lib/python3.7/http/client.py", line 1369, in getresponse
    response.begin()
  File "/usr/lib/python3.7/http/client.py", line 310, in begin
    version, status, reason = self._read_status()
  File "/usr/lib/python3.7/http/client.py", line 279, in _read_status
    raise RemoteDisconnected("Remote end closed connection without"
http.client.RemoteDisconnected: Remote end closed connection without response

During handling of the above exception, another exception occurred:

Traceback (most recent call last):
  File "/usr/lib/python3/dist-packages/requests/adapters.py", line 449, in send
    timeout=timeout
  File "/usr/lib/python3/dist-packages/urllib3/connectionpool.py", line 720, in urlopen
    method, url, error=e, _pool=self, _stacktrace=sys.exc_info()[2]
  File "/usr/lib/python3/dist-packages/urllib3/util/retry.py", line 400, in increment
    raise six.reraise(type(error), error, _stacktrace)
  File "/usr/lib/python3/dist-packages/six.py", line 702, in reraise
    raise value.with_traceback(tb)
  File "/usr/lib/python3/dist-packages/urllib3/connectionpool.py", line 672, in urlopen
    chunked=chunked,
  File "/usr/lib/python3/dist-packages/urllib3/connectionpool.py", line 421, in _make_request
    six.raise_from(e, None)
  File "<string>", line 3, in raise_from
  File "/usr/lib/python3/dist-packages/urllib3/connectionpool.py", line 416, in _make_request
    httplib_response = conn.getresponse()
  File "/usr/lib/python3.7/http/client.py", line 1369, in getresponse
    response.begin()
  File "/usr/lib/python3.7/http/client.py", line 310, in begin
    version, status, reason = self._read_status()
  File "/usr/lib/python3.7/http/client.py", line 279, in _read_status
    raise RemoteDisconnected("Remote end closed connection without"
urllib3.exceptions.ProtocolError: ('Connection aborted.', RemoteDisconnected('Remote end closed connection without response'))

During handling of the above exception, another exception occurred:

Traceback (most recent call last):
  File "v8function_handler.pyx", line 48, in cefpython_py37.V8FunctionHandler_Execute
  File "/media/feodoritiy/HDD/CODE/VS_C+/fti/Cursach/client/logic/create_game.py", line 10, in create_game
    'host': f'{storage.SOCKET_HOST}:{storage.SOCKET_PORT}',
  File "/media/feodoritiy/HDD/CODE/VS_C+/fti/Cursach/client/storage.py", line 24, in load
    res = requests.post(f'{SERVER}{path}', data)
  File "/usr/lib/python3/dist-packages/requests/api.py", line 116, in post
    return request('post', url, data=data, json=json, **kwargs)
  File "/usr/lib/python3/dist-packages/requests/api.py", line 60, in request
    return session.request(method=method, url=url, **kwargs)
  File "/usr/lib/python3/dist-packages/requests/sessions.py", line 533, in request
    resp = self.send(prep, **send_kwargs)
  File "/usr/lib/python3/dist-packages/requests/sessions.py", line 646, in send
    r = adapter.send(request, **kwargs)
  File "/usr/lib/python3/dist-packages/requests/adapters.py", line 498, in send
    raise ConnectionError(err, request=request)
requests.exceptions.ConnectionError: ('Connection aborted.', RemoteDisconnected('Remote end closed connection without response'))


[2021-04-14 05:16:09] Traceback (most recent call last):
  File "/usr/lib/python3/dist-packages/urllib3/connectionpool.py", line 672, in urlopen
    chunked=chunked,
  File "/usr/lib/python3/dist-packages/urllib3/connectionpool.py", line 421, in _make_request
    six.raise_from(e, None)
  File "<string>", line 3, in raise_from
  File "/usr/lib/python3/dist-packages/urllib3/connectionpool.py", line 416, in _make_request
    httplib_response = conn.getresponse()
  File "/usr/lib/python3.7/http/client.py", line 1369, in getresponse
    response.begin()
  File "/usr/lib/python3.7/http/client.py", line 310, in begin
    version, status, reason = self._read_status()
  File "/usr/lib/python3.7/http/client.py", line 279, in _read_status
    raise RemoteDisconnected("Remote end closed connection without"
http.client.RemoteDisconnected: Remote end closed connection without response

During handling of the above exception, another exception occurred:

Traceback (most recent call last):
  File "/usr/lib/python3/dist-packages/requests/adapters.py", line 449, in send
    timeout=timeout
  File "/usr/lib/python3/dist-packages/urllib3/connectionpool.py", line 720, in urlopen
    method, url, error=e, _pool=self, _stacktrace=sys.exc_info()[2]
  File "/usr/lib/python3/dist-packages/urllib3/util/retry.py", line 400, in increment
    raise six.reraise(type(error), error, _stacktrace)
  File "/usr/lib/python3/dist-packages/six.py", line 702, in reraise
    raise value.with_traceback(tb)
  File "/usr/lib/python3/dist-packages/urllib3/connectionpool.py", line 672, in urlopen
    chunked=chunked,
  File "/usr/lib/python3/dist-packages/urllib3/connectionpool.py", line 421, in _make_request
    six.raise_from(e, None)
  File "<string>", line 3, in raise_from
  File "/usr/lib/python3/dist-packages/urllib3/connectionpool.py", line 416, in _make_request
    httplib_response = conn.getresponse()
  File "/usr/lib/python3.7/http/client.py", line 1369, in getresponse
    response.begin()
  File "/usr/lib/python3.7/http/client.py", line 310, in begin
    version, status, reason = self._read_status()
  File "/usr/lib/python3.7/http/client.py", line 279, in _read_status
    raise RemoteDisconnected("Remote end closed connection without"
urllib3.exceptions.ProtocolError: ('Connection aborted.', RemoteDisconnected('Remote end closed connection without response'))

During handling of the above exception, another exception occurred:

Traceback (most recent call last):
  File "v8function_handler.pyx", line 48, in cefpython_py37.V8FunctionHandler_Execute
  File "/media/feodoritiy/HDD/CODE/VS_C+/fti/Cursach/client/logic/create_game.py", line 10, in create_game
    'host': f'{storage.SOCKET_HOST}:{storage.SOCKET_PORT}',
  File "/media/feodoritiy/HDD/CODE/VS_C+/fti/Cursach/client/storage.py", line 24, in load
    res = requests.post(f'{SERVER}{path}', data)
  File "/usr/lib/python3/dist-packages/requests/api.py", line 116, in post
    return request('post', url, data=data, json=json, **kwargs)
  File "/usr/lib/python3/dist-packages/requests/api.py", line 60, in request
    return session.request(method=method, url=url, **kwargs)
  File "/usr/lib/python3/dist-packages/requests/sessions.py", line 533, in request
    resp = self.send(prep, **send_kwargs)
  File "/usr/lib/python3/dist-packages/requests/sessions.py", line 646, in send
    r = adapter.send(request, **kwargs)
  File "/usr/lib/python3/dist-packages/requests/adapters.py", line 498, in send
    raise ConnectionError(err, request=request)
requests.exceptions.ConnectionError: ('Connection aborted.', RemoteDisconnected('Remote end closed connection without response'))


[2021-04-14 10:43:20] Traceback (most recent call last):
  File "v8function_handler.pyx", line 48, in cefpython_py37.V8FunctionHandler_Execute
  File "/media/feodoritiy/HDD/CODE/VS_C+/fti/Cursach/client/logic/create_game.py", line 10, in create_game
    'host': f'{storage.SOCKET_HOST}:{storage.SOCKET_PORT}',
AttributeError: module 'storage' has no attribute 'SOCKET_HOST'


[2021-04-15 08:57:48] Traceback (most recent call last):
  File "v8function_handler.pyx", line 48, in cefpython_py37.V8FunctionHandler_Execute
  File "/media/feodoritiy/HDD/CODE/VS_C+/fti/Cursach/client/logic/connect_game.py", line 13, in connect_game
    if res['status'] == 'OK':
TypeError: 'Response' object is not subscriptable


[2021-04-15 08:59:21] Traceback (most recent call last):
  File "v8function_handler.pyx", line 48, in cefpython_py37.V8FunctionHandler_Execute
  File "/media/feodoritiy/HDD/CODE/VS_C+/fti/Cursach/client/logic/connect_game.py", line 13, in connect_game
    if res['status'] == 'OK':
TypeError: 'Response' object is not subscriptable


[2021-04-15 12:24:12] Traceback (most recent call last):
  File "v8function_handler.pyx", line 48, in cefpython_py37.V8FunctionHandler_Execute
  File "/media/feodoritiy/HDD/CODE/VS_C+/fti/Cursach/client/logic/create_game.py", line 16, in create_game
    storage.connect('/game', {})
  File "/media/feodoritiy/HDD/CODE/VS_C+/fti/Cursach/client/storage.py", line 47, in connect
    if not hasattr(storage, 'id') and not storage.id:
NameError: name 'storage' is not defined


[2021-04-15 12:25:28] Traceback (most recent call last):
  File "v8function_handler.pyx", line 48, in cefpython_py37.V8FunctionHandler_Execute
  File "/media/feodoritiy/HDD/CODE/VS_C+/fti/Cursach/client/logic/connect_game.py", line 13, in connect_game
    if res['status'] == 'OK':
TypeError: 'Response' object is not subscriptable


[2021-04-15 12:26:32] Traceback (most recent call last):
  File "v8function_handler.pyx", line 48, in cefpython_py37.V8FunctionHandler_Execute
  File "/media/feodoritiy/HDD/CODE/VS_C+/fti/Cursach/client/logic/connect_game.py", line 13, in connect_game
    if res['status'] == 'OK':
TypeError: 'Response' object is not subscriptable


[2021-04-15 12:27:09] Traceback (most recent call last):
  File "v8function_handler.pyx", line 48, in cefpython_py37.V8FunctionHandler_Execute
  File "/media/feodoritiy/HDD/CODE/VS_C+/fti/Cursach/client/logic/connect_game.py", line 13, in connect_game
    if res['status'] == 'OK':
TypeError: 'Response' object is not subscriptable


[2021-04-15 12:28:47] Traceback (most recent call last):
  File "v8function_handler.pyx", line 48, in cefpython_py37.V8FunctionHandler_Execute
  File "/media/feodoritiy/HDD/CODE/VS_C+/fti/Cursach/client/logic/connect_game.py", line 13, in connect_game
    if res['status'] == 'OK':
TypeError: 'Response' object is not subscriptable


[2021-04-15 12:50:31] Traceback (most recent call last):
  File "/usr/lib/python3/dist-packages/urllib3/connection.py", line 160, in _new_conn
    (self._dns_host, self.port), self.timeout, **extra_kw
  File "/usr/lib/python3/dist-packages/urllib3/util/connection.py", line 84, in create_connection
    raise err
  File "/usr/lib/python3/dist-packages/urllib3/util/connection.py", line 74, in create_connection
    sock.connect(sa)
ConnectionRefusedError: [Errno 111] Connection refused

During handling of the above exception, another exception occurred:

Traceback (most recent call last):
  File "/usr/lib/python3/dist-packages/urllib3/connectionpool.py", line 672, in urlopen
    chunked=chunked,
  File "/usr/lib/python3/dist-packages/urllib3/connectionpool.py", line 387, in _make_request
    conn.request(method, url, **httplib_request_kw)
  File "/usr/lib/python3.7/http/client.py", line 1277, in request
    self._send_request(method, url, body, headers, encode_chunked)
  File "/usr/lib/python3.7/http/client.py", line 1323, in _send_request
    self.endheaders(body, encode_chunked=encode_chunked)
  File "/usr/lib/python3.7/http/client.py", line 1272, in endheaders
    self._send_output(message_body, encode_chunked=encode_chunked)
  File "/usr/lib/python3.7/http/client.py", line 1032, in _send_output
    self.send(msg)
  File "/usr/lib/python3.7/http/client.py", line 972, in send
    self.connect()
  File "/usr/lib/python3/dist-packages/urllib3/connection.py", line 187, in connect
    conn = self._new_conn()
  File "/usr/lib/python3/dist-packages/urllib3/connection.py", line 172, in _new_conn
    self, "Failed to establish a new connection: %s" % e
urllib3.exceptions.NewConnectionError: <urllib3.connection.HTTPConnection object at 0x7ff895241c10>: Failed to establish a new connection: [Errno 111] Connection refused

During handling of the above exception, another exception occurred:

Traceback (most recent call last):
  File "/usr/lib/python3/dist-packages/requests/adapters.py", line 449, in send
    timeout=timeout
  File "/usr/lib/python3/dist-packages/urllib3/connectionpool.py", line 720, in urlopen
    method, url, error=e, _pool=self, _stacktrace=sys.exc_info()[2]
  File "/usr/lib/python3/dist-packages/urllib3/util/retry.py", line 436, in increment
    raise MaxRetryError(_pool, url, error or ResponseError(cause))
urllib3.exceptions.MaxRetryError: HTTPConnectionPool(host='127.0.0.1', port=1234): Max retries exceeded with url: /login (Caused by NewConnectionError('<urllib3.connection.HTTPConnection object at 0x7ff895241c10>: Failed to establish a new connection: [Errno 111] Connection refused'))

During handling of the above exception, another exception occurred:

Traceback (most recent call last):
  File "v8function_handler.pyx", line 48, in cefpython_py37.V8FunctionHandler_Execute
  File "/media/feodoritiy/HDD/CODE/VS_C+/fti/Cursach/client/logic/login.py", line 10, in login
    'password': password,
  File "/media/feodoritiy/HDD/CODE/VS_C+/fti/Cursach/client/storage.py", line 22, in load
    res = requests.post(f'{SERVER}{path}', data)
  File "/usr/lib/python3/dist-packages/requests/api.py", line 116, in post
    return request('post', url, data=data, json=json, **kwargs)
  File "/usr/lib/python3/dist-packages/requests/api.py", line 60, in request
    return session.request(method=method, url=url, **kwargs)
  File "/usr/lib/python3/dist-packages/requests/sessions.py", line 533, in request
    resp = self.send(prep, **send_kwargs)
  File "/usr/lib/python3/dist-packages/requests/sessions.py", line 646, in send
    r = adapter.send(request, **kwargs)
  File "/usr/lib/python3/dist-packages/requests/adapters.py", line 516, in send
    raise ConnectionError(e, request=request)
requests.exceptions.ConnectionError: HTTPConnectionPool(host='127.0.0.1', port=1234): Max retries exceeded with url: /login (Caused by NewConnectionError('<urllib3.connection.HTTPConnection object at 0x7ff895241c10>: Failed to establish a new connection: [Errno 111] Connection refused'))


[2021-04-16 14:12:15] Traceback (most recent call last):
  File "lifespan_handler.pyx", line 129, in cefpython_py37.LifespanHandler_OnBeforeClose
  File "/media/feodoritiy/HDD/CODE/VS_C+/fti/Cursach/client/browser.py", line 85, in OnBeforeClose
    print(f'Broswer ID: {browser.GetIndetifier()}')
AttributeError: 'cefpython_py37.PyBrowser' object has no attribute 'GetIndetifier'


[2021-04-16 16:42:10] Traceback (most recent call last):
  File "lifespan_handler.pyx", line 129, in cefpython_py37.LifespanHandler_OnBeforeClose
  File "/media/feodoritiy/HDD/CODE/VS_C+/fti/Cursach/client/browser.py", line 87, in OnBeforeClose
    storage.connection_process.terminate()
AttributeError: 'NoneType' object has no attribute 'terminate'


[2021-04-16 18:20:53] Traceback (most recent call last):
  File "v8function_handler.pyx", line 48, in cefpython_py37.V8FunctionHandler_Execute
  File "/media/feodoritiy/HDD/CODE/VS_C+/fti/Cursach/client/logic/connect_game.py", line 21, in connect_game
    if res['status'] == 'OK':
TypeError: 'Response' object is not subscriptable


[2021-04-16 21:59:38] Traceback (most recent call last):
  File "lifespan_handler.pyx", line 129, in cefpython_py37.LifespanHandler_OnBeforeClose
  File "/media/feodoritiy/HDD/CODE/VS_C+/fti/Cursach/client/browser.py", line 95, in OnBeforeClose
    storage.connection_process.terminate()
AttributeError: 'NoneType' object has no attribute 'terminate'


[2021-04-16 22:19:14] Traceback (most recent call last):
  File "lifespan_handler.pyx", line 129, in cefpython_py37.LifespanHandler_OnBeforeClose
  File "/media/feodoritiy/HDD/CODE/VS_C+/fti/Cursach/client/browser.py", line 95, in OnBeforeClose
    storage.connection_process.terminate()
AttributeError: 'NoneType' object has no attribute 'terminate'


[2021-04-16 22:38:51] Traceback (most recent call last):
  File "lifespan_handler.pyx", line 129, in cefpython_py37.LifespanHandler_OnBeforeClose
  File "/media/feodoritiy/HDD/CODE/VS_C+/fti/Cursach/client/browser.py", line 97, in OnBeforeClose
    storage.connection_process.terminate()
AttributeError: 'NoneType' object has no attribute 'terminate'


[2021-04-16 23:13:39] Traceback (most recent call last):
  File "v8function_handler.pyx", line 48, in cefpython_py37.V8FunctionHandler_Execute
  File "/media/feodoritiy/HDD/CODE/VS_C+/fti/Cursach/client/logic/game.py", line 60, in get_tasks
    while not storage.queue.empty():
AttributeError: module 'storage' has no attribute 'queue'


[2021-04-16 23:15:36] Traceback (most recent call last):
  File "lifespan_handler.pyx", line 129, in cefpython_py37.LifespanHandler_OnBeforeClose
  File "/media/feodoritiy/HDD/CODE/VS_C+/fti/Cursach/client/browser.py", line 97, in OnBeforeClose
    storage.connection_process.terminate()
AttributeError: 'NoneType' object has no attribute 'terminate'


[2021-04-17 00:11:04] Traceback (most recent call last):
  File "v8function_handler.pyx", line 48, in cefpython_py37.V8FunctionHandler_Execute
  File "/media/feodoritiy/HDD/CODE/VS_C+/fti/Cursach/client/logic/game.py", line 63, in get_tasks
    print('getTasks: some tasks', '; '.join([f'{t[0]}(' + ', '.join(t[1]) + ')' for t in tasks]))
  File "/media/feodoritiy/HDD/CODE/VS_C+/fti/Cursach/client/logic/game.py", line 63, in <listcomp>
    print('getTasks: some tasks', '; '.join([f'{t[0]}(' + ', '.join(t[1]) + ')' for t in tasks]))
TypeError: sequence item 0: expected str instance, int found


[2021-04-17 00:20:57] Traceback (most recent call last):
  File "lifespan_handler.pyx", line 129, in cefpython_py37.LifespanHandler_OnBeforeClose
  File "/media/feodoritiy/HDD/CODE/VS_C+/fti/Cursach/client/browser.py", line 97, in OnBeforeClose
    storage.connection_process.terminate()
AttributeError: 'NoneType' object has no attribute 'terminate'


[2021-04-17 00:35:04] Traceback (most recent call last):
  File "lifespan_handler.pyx", line 129, in cefpython_py37.LifespanHandler_OnBeforeClose
  File "/media/feodoritiy/HDD/CODE/VS_C+/fti/Cursach/client/browser.py", line 97, in OnBeforeClose
    storage.connection_process.terminate()
AttributeError: 'NoneType' object has no attribute 'terminate'


[2021-04-17 00:46:00] Traceback (most recent call last):
  File "lifespan_handler.pyx", line 129, in cefpython_py37.LifespanHandler_OnBeforeClose
  File "/media/feodoritiy/HDD/CODE/VS_C+/fti/Cursach/client/browser.py", line 97, in OnBeforeClose
    storage.connection_process.terminate()
AttributeError: 'NoneType' object has no attribute 'terminate'


[2021-04-17 01:03:29] Traceback (most recent call last):
  File "lifespan_handler.pyx", line 129, in cefpython_py37.LifespanHandler_OnBeforeClose
  File "/media/feodoritiy/HDD/CODE/VS_C+/fti/Cursach/client/browser.py", line 97, in OnBeforeClose
    storage.connection_process.terminate()
AttributeError: 'NoneType' object has no attribute 'terminate'


[2021-04-17 01:04:37] Traceback (most recent call last):
  File "v8function_handler.pyx", line 48, in cefpython_py37.V8FunctionHandler_Execute
  File "/media/feodoritiy/HDD/CODE/VS_C+/fti/Cursach/client/logic/game.py", line 49, in get_skin
    callback.Call(res['skin'])
TypeError: 'NoneType' object is not subscriptable


[2021-04-17 03:46:06] Traceback (most recent call last):
  File "/usr/lib/python3/dist-packages/urllib3/connection.py", line 160, in _new_conn
    (self._dns_host, self.port), self.timeout, **extra_kw
  File "/usr/lib/python3/dist-packages/urllib3/util/connection.py", line 84, in create_connection
    raise err
  File "/usr/lib/python3/dist-packages/urllib3/util/connection.py", line 74, in create_connection
    sock.connect(sa)
ConnectionRefusedError: [Errno 111] Connection refused

During handling of the above exception, another exception occurred:

Traceback (most recent call last):
  File "/usr/lib/python3/dist-packages/urllib3/connectionpool.py", line 672, in urlopen
    chunked=chunked,
  File "/usr/lib/python3/dist-packages/urllib3/connectionpool.py", line 387, in _make_request
    conn.request(method, url, **httplib_request_kw)
  File "/usr/lib/python3.7/http/client.py", line 1277, in request
    self._send_request(method, url, body, headers, encode_chunked)
  File "/usr/lib/python3.7/http/client.py", line 1323, in _send_request
    self.endheaders(body, encode_chunked=encode_chunked)
  File "/usr/lib/python3.7/http/client.py", line 1272, in endheaders
    self._send_output(message_body, encode_chunked=encode_chunked)
  File "/usr/lib/python3.7/http/client.py", line 1032, in _send_output
    self.send(msg)
  File "/usr/lib/python3.7/http/client.py", line 972, in send
    self.connect()
  File "/usr/lib/python3/dist-packages/urllib3/connection.py", line 187, in connect
    conn = self._new_conn()
  File "/usr/lib/python3/dist-packages/urllib3/connection.py", line 172, in _new_conn
    self, "Failed to establish a new connection: %s" % e
urllib3.exceptions.NewConnectionError: <urllib3.connection.HTTPConnection object at 0x7f57f02e93d0>: Failed to establish a new connection: [Errno 111] Connection refused

During handling of the above exception, another exception occurred:

Traceback (most recent call last):
  File "/usr/lib/python3/dist-packages/requests/adapters.py", line 449, in send
    timeout=timeout
  File "/usr/lib/python3/dist-packages/urllib3/connectionpool.py", line 720, in urlopen
    method, url, error=e, _pool=self, _stacktrace=sys.exc_info()[2]
  File "/usr/lib/python3/dist-packages/urllib3/util/retry.py", line 436, in increment
    raise MaxRetryError(_pool, url, error or ResponseError(cause))
urllib3.exceptions.MaxRetryError: HTTPConnectionPool(host='127.0.0.1', port=1234): Max retries exceeded with url: /login (Caused by NewConnectionError('<urllib3.connection.HTTPConnection object at 0x7f57f02e93d0>: Failed to establish a new connection: [Errno 111] Connection refused'))

During handling of the above exception, another exception occurred:

Traceback (most recent call last):
  File "v8function_handler.pyx", line 48, in cefpython_py37.V8FunctionHandler_Execute
  File "/media/feodoritiy/HDD/CODE/VS_C+/fti/Cursach/client/logic/login.py", line 10, in login
    'password': password,
  File "/media/feodoritiy/HDD/CODE/VS_C+/fti/Cursach/client/storage.py", line 36, in load
    res = requests.post(f'{SERVER}{path}', data)
  File "/usr/lib/python3/dist-packages/requests/api.py", line 116, in post
    return request('post', url, data=data, json=json, **kwargs)
  File "/usr/lib/python3/dist-packages/requests/api.py", line 60, in request
    return session.request(method=method, url=url, **kwargs)
  File "/usr/lib/python3/dist-packages/requests/sessions.py", line 533, in request
    resp = self.send(prep, **send_kwargs)
  File "/usr/lib/python3/dist-packages/requests/sessions.py", line 646, in send
    r = adapter.send(request, **kwargs)
  File "/usr/lib/python3/dist-packages/requests/adapters.py", line 516, in send
    raise ConnectionError(e, request=request)
requests.exceptions.ConnectionError: HTTPConnectionPool(host='127.0.0.1', port=1234): Max retries exceeded with url: /login (Caused by NewConnectionError('<urllib3.connection.HTTPConnection object at 0x7f57f02e93d0>: Failed to establish a new connection: [Errno 111] Connection refused'))


[2021-04-17 03:56:05] Traceback (most recent call last):
  File "/usr/lib/python3/dist-packages/urllib3/connection.py", line 160, in _new_conn
    (self._dns_host, self.port), self.timeout, **extra_kw
  File "/usr/lib/python3/dist-packages/urllib3/util/connection.py", line 84, in create_connection
    raise err
  File "/usr/lib/python3/dist-packages/urllib3/util/connection.py", line 74, in create_connection
    sock.connect(sa)
ConnectionRefusedError: [Errno 111] Connection refused

During handling of the above exception, another exception occurred:

Traceback (most recent call last):
  File "/usr/lib/python3/dist-packages/urllib3/connectionpool.py", line 672, in urlopen
    chunked=chunked,
  File "/usr/lib/python3/dist-packages/urllib3/connectionpool.py", line 387, in _make_request
    conn.request(method, url, **httplib_request_kw)
  File "/usr/lib/python3.7/http/client.py", line 1277, in request
    self._send_request(method, url, body, headers, encode_chunked)
  File "/usr/lib/python3.7/http/client.py", line 1323, in _send_request
    self.endheaders(body, encode_chunked=encode_chunked)
  File "/usr/lib/python3.7/http/client.py", line 1272, in endheaders
    self._send_output(message_body, encode_chunked=encode_chunked)
  File "/usr/lib/python3.7/http/client.py", line 1032, in _send_output
    self.send(msg)
  File "/usr/lib/python3.7/http/client.py", line 972, in send
    self.connect()
  File "/usr/lib/python3/dist-packages/urllib3/connection.py", line 187, in connect
    conn = self._new_conn()
  File "/usr/lib/python3/dist-packages/urllib3/connection.py", line 172, in _new_conn
    self, "Failed to establish a new connection: %s" % e
urllib3.exceptions.NewConnectionError: <urllib3.connection.HTTPConnection object at 0x7fec1c31d690>: Failed to establish a new connection: [Errno 111] Connection refused

During handling of the above exception, another exception occurred:

Traceback (most recent call last):
  File "/usr/lib/python3/dist-packages/requests/adapters.py", line 449, in send
    timeout=timeout
  File "/usr/lib/python3/dist-packages/urllib3/connectionpool.py", line 720, in urlopen
    method, url, error=e, _pool=self, _stacktrace=sys.exc_info()[2]
  File "/usr/lib/python3/dist-packages/urllib3/util/retry.py", line 436, in increment
    raise MaxRetryError(_pool, url, error or ResponseError(cause))
urllib3.exceptions.MaxRetryError: HTTPConnectionPool(host='127.0.0.1', port=1234): Max retries exceeded with url: /game (Caused by NewConnectionError('<urllib3.connection.HTTPConnection object at 0x7fec1c31d690>: Failed to establish a new connection: [Errno 111] Connection refused'))

During handling of the above exception, another exception occurred:

Traceback (most recent call last):
  File "v8function_handler.pyx", line 48, in cefpython_py37.V8FunctionHandler_Execute
  File "/media/feodoritiy/HDD/CODE/VS_C+/fti/Cursach/client/logic/game.py", line 86, in send_disconnect
    storage.gameload('disconnect', {})
  File "/media/feodoritiy/HDD/CODE/VS_C+/fti/Cursach/client/storage.py", line 53, in gameload
    return this.load('/game', final_data)
  File "/media/feodoritiy/HDD/CODE/VS_C+/fti/Cursach/client/storage.py", line 36, in load
    res = requests.post(f'{SERVER}{path}', data)
  File "/usr/lib/python3/dist-packages/requests/api.py", line 116, in post
    return request('post', url, data=data, json=json, **kwargs)
  File "/usr/lib/python3/dist-packages/requests/api.py", line 60, in request
    return session.request(method=method, url=url, **kwargs)
  File "/usr/lib/python3/dist-packages/requests/sessions.py", line 533, in request
    resp = self.send(prep, **send_kwargs)
  File "/usr/lib/python3/dist-packages/requests/sessions.py", line 646, in send
    r = adapter.send(request, **kwargs)
  File "/usr/lib/python3/dist-packages/requests/adapters.py", line 516, in send
    raise ConnectionError(e, request=request)
requests.exceptions.ConnectionError: HTTPConnectionPool(host='127.0.0.1', port=1234): Max retries exceeded with url: /game (Caused by NewConnectionError('<urllib3.connection.HTTPConnection object at 0x7fec1c31d690>: Failed to establish a new connection: [Errno 111] Connection refused'))


[2021-04-17 04:32:47] Traceback (most recent call last):
  File "v8function_handler.pyx", line 48, in cefpython_py37.V8FunctionHandler_Execute
  File "/media/feodoritiy/HDD/CODE/VS_C+/fti/Cursach/client/logic/create_game.py", line 25, in create_game
    storage.connection_count = res['connection_count']
KeyError: 'connection_count'


[2021-04-17 04:33:17] Traceback (most recent call last):
  File "v8function_handler.pyx", line 48, in cefpython_py37.V8FunctionHandler_Execute
  File "/media/feodoritiy/HDD/CODE/VS_C+/fti/Cursach/client/logic/create_game.py", line 25, in create_game
    storage.connection_count = res['connection_count']
KeyError: 'connection_count'


[2021-04-17 04:37:41] Traceback (most recent call last):
  File "lifespan_handler.pyx", line 129, in cefpython_py37.LifespanHandler_OnBeforeClose
  File "/media/feodoritiy/HDD/CODE/VS_C+/fti/Cursach/client/browser.py", line 97, in OnBeforeClose
    storage.connection_process.terminate()
AttributeError: 'NoneType' object has no attribute 'terminate'


[2021-04-17 04:42:20] Traceback (most recent call last):
  File "v8function_handler.pyx", line 48, in cefpython_py37.V8FunctionHandler_Execute
  File "/media/feodoritiy/HDD/CODE/VS_C+/fti/Cursach/client/logic/connect_game.py", line 20, in connect_game
    if res['status'] == 'OK':
TypeError: 'Response' object is not subscriptable


[2021-04-17 12:53:07] Traceback (most recent call last):
  File "lifespan_handler.pyx", line 129, in cefpython_py37.LifespanHandler_OnBeforeClose
  File "/media/feodoritiy/HDD/CODE/VS_C+/fti/Cursach/client/browser.py", line 97, in OnBeforeClose
    storage.connection_process.terminate()
AttributeError: 'NoneType' object has no attribute 'terminate'


[2021-04-17 12:59:55] Traceback (most recent call last):
  File "/usr/lib/python3/dist-packages/urllib3/connection.py", line 160, in _new_conn
    (self._dns_host, self.port), self.timeout, **extra_kw
  File "/usr/lib/python3/dist-packages/urllib3/util/connection.py", line 84, in create_connection
    raise err
  File "/usr/lib/python3/dist-packages/urllib3/util/connection.py", line 74, in create_connection
    sock.connect(sa)
ConnectionRefusedError: [Errno 111] Connection refused

During handling of the above exception, another exception occurred:

Traceback (most recent call last):
  File "/usr/lib/python3/dist-packages/urllib3/connectionpool.py", line 672, in urlopen
    chunked=chunked,
  File "/usr/lib/python3/dist-packages/urllib3/connectionpool.py", line 387, in _make_request
    conn.request(method, url, **httplib_request_kw)
  File "/usr/lib/python3.7/http/client.py", line 1277, in request
    self._send_request(method, url, body, headers, encode_chunked)
  File "/usr/lib/python3.7/http/client.py", line 1323, in _send_request
    self.endheaders(body, encode_chunked=encode_chunked)
  File "/usr/lib/python3.7/http/client.py", line 1272, in endheaders
    self._send_output(message_body, encode_chunked=encode_chunked)
  File "/usr/lib/python3.7/http/client.py", line 1032, in _send_output
    self.send(msg)
  File "/usr/lib/python3.7/http/client.py", line 972, in send
    self.connect()
  File "/usr/lib/python3/dist-packages/urllib3/connection.py", line 187, in connect
    conn = self._new_conn()
  File "/usr/lib/python3/dist-packages/urllib3/connection.py", line 172, in _new_conn
    self, "Failed to establish a new connection: %s" % e
urllib3.exceptions.NewConnectionError: <urllib3.connection.HTTPConnection object at 0x7f203c1e3290>: Failed to establish a new connection: [Errno 111] Connection refused

During handling of the above exception, another exception occurred:

Traceback (most recent call last):
  File "/usr/lib/python3/dist-packages/requests/adapters.py", line 449, in send
    timeout=timeout
  File "/usr/lib/python3/dist-packages/urllib3/connectionpool.py", line 720, in urlopen
    method, url, error=e, _pool=self, _stacktrace=sys.exc_info()[2]
  File "/usr/lib/python3/dist-packages/urllib3/util/retry.py", line 436, in increment
    raise MaxRetryError(_pool, url, error or ResponseError(cause))
urllib3.exceptions.MaxRetryError: HTTPConnectionPool(host='127.0.0.1', port=1234): Max retries exceeded with url: /game (Caused by NewConnectionError('<urllib3.connection.HTTPConnection object at 0x7f203c1e3290>: Failed to establish a new connection: [Errno 111] Connection refused'))

During handling of the above exception, another exception occurred:

Traceback (most recent call last):
  File "v8function_handler.pyx", line 48, in cefpython_py37.V8FunctionHandler_Execute
  File "/media/feodoritiy/HDD/CODE/VS_C+/fti/Cursach/client/logic/game.py", line 90, in send_disconnect
    storage.gameload('disconnect', {})
  File "/media/feodoritiy/HDD/CODE/VS_C+/fti/Cursach/client/storage.py", line 53, in gameload
    return this.load('/game', final_data)
  File "/media/feodoritiy/HDD/CODE/VS_C+/fti/Cursach/client/storage.py", line 36, in load
    res = requests.post(f'{SERVER}{path}', data)
  File "/usr/lib/python3/dist-packages/requests/api.py", line 116, in post
    return request('post', url, data=data, json=json, **kwargs)
  File "/usr/lib/python3/dist-packages/requests/api.py", line 60, in request
    return session.request(method=method, url=url, **kwargs)
  File "/usr/lib/python3/dist-packages/requests/sessions.py", line 533, in request
    resp = self.send(prep, **send_kwargs)
  File "/usr/lib/python3/dist-packages/requests/sessions.py", line 646, in send
    r = adapter.send(request, **kwargs)
  File "/usr/lib/python3/dist-packages/requests/adapters.py", line 516, in send
    raise ConnectionError(e, request=request)
requests.exceptions.ConnectionError: HTTPConnectionPool(host='127.0.0.1', port=1234): Max retries exceeded with url: /game (Caused by NewConnectionError('<urllib3.connection.HTTPConnection object at 0x7f203c1e3290>: Failed to establish a new connection: [Errno 111] Connection refused'))


[2021-04-17 13:46:23] Traceback (most recent call last):
  File "v8function_handler.pyx", line 48, in cefpython_py37.V8FunctionHandler_Execute
  File "/media/feodoritiy/HDD/CODE/VS_C+/fti/Cursach/client/logic/create_game.py", line 12, in create_game
    if res['status'] == 'OK':
TypeError: 'Response' object is not subscriptable


[2021-04-17 14:02:42] Traceback (most recent call last):
  File "lifespan_handler.pyx", line 129, in cefpython_py37.LifespanHandler_OnBeforeClose
  File "/media/feodoritiy/HDD/CODE/VS_C+/fti/Cursach/client/browser.py", line 97, in OnBeforeClose
    storage.connection_process.terminate()
AttributeError: 'NoneType' object has no attribute 'terminate'


[2021-04-17 14:56:50] Traceback (most recent call last):
  File "lifespan_handler.pyx", line 129, in cefpython_py37.LifespanHandler_OnBeforeClose
  File "/media/feodoritiy/HDD/CODE/VS_C+/fti/Cursach/client/browser.py", line 97, in OnBeforeClose
    storage.connection_process.terminate()
AttributeError: 'NoneType' object has no attribute 'terminate'


[2021-04-17 16:58:18] Traceback (most recent call last):
  File "lifespan_handler.pyx", line 129, in cefpython_py37.LifespanHandler_OnBeforeClose
  File "/media/feodoritiy/HDD/CODE/VS_C+/fti/Cursach/client/browser.py", line 97, in OnBeforeClose
    storage.connection_process.terminate()
AttributeError: 'NoneType' object has no attribute 'terminate'


[2021-04-17 17:35:24] Traceback (most recent call last):
  File "/usr/lib/python3/dist-packages/urllib3/connection.py", line 160, in _new_conn
    (self._dns_host, self.port), self.timeout, **extra_kw
  File "/usr/lib/python3/dist-packages/urllib3/util/connection.py", line 84, in create_connection
    raise err
  File "/usr/lib/python3/dist-packages/urllib3/util/connection.py", line 74, in create_connection
    sock.connect(sa)
ConnectionRefusedError: [Errno 111] Connection refused

During handling of the above exception, another exception occurred:

Traceback (most recent call last):
  File "/usr/lib/python3/dist-packages/urllib3/connectionpool.py", line 672, in urlopen
    chunked=chunked,
  File "/usr/lib/python3/dist-packages/urllib3/connectionpool.py", line 387, in _make_request
    conn.request(method, url, **httplib_request_kw)
  File "/usr/lib/python3.7/http/client.py", line 1277, in request
    self._send_request(method, url, body, headers, encode_chunked)
  File "/usr/lib/python3.7/http/client.py", line 1323, in _send_request
    self.endheaders(body, encode_chunked=encode_chunked)
  File "/usr/lib/python3.7/http/client.py", line 1272, in endheaders
    self._send_output(message_body, encode_chunked=encode_chunked)
  File "/usr/lib/python3.7/http/client.py", line 1032, in _send_output
    self.send(msg)
  File "/usr/lib/python3.7/http/client.py", line 972, in send
    self.connect()
  File "/usr/lib/python3/dist-packages/urllib3/connection.py", line 187, in connect
    conn = self._new_conn()
  File "/usr/lib/python3/dist-packages/urllib3/connection.py", line 172, in _new_conn
    self, "Failed to establish a new connection: %s" % e
urllib3.exceptions.NewConnectionError: <urllib3.connection.HTTPConnection object at 0x7fa7084d8c50>: Failed to establish a new connection: [Errno 111] Connection refused

During handling of the above exception, another exception occurred:

Traceback (most recent call last):
  File "/usr/lib/python3/dist-packages/requests/adapters.py", line 449, in send
    timeout=timeout
  File "/usr/lib/python3/dist-packages/urllib3/connectionpool.py", line 720, in urlopen
    method, url, error=e, _pool=self, _stacktrace=sys.exc_info()[2]
  File "/usr/lib/python3/dist-packages/urllib3/util/retry.py", line 436, in increment
    raise MaxRetryError(_pool, url, error or ResponseError(cause))
urllib3.exceptions.MaxRetryError: HTTPConnectionPool(host='127.0.0.1', port=1234): Max retries exceeded with url: /login (Caused by NewConnectionError('<urllib3.connection.HTTPConnection object at 0x7fa7084d8c50>: Failed to establish a new connection: [Errno 111] Connection refused'))

During handling of the above exception, another exception occurred:

Traceback (most recent call last):
  File "v8function_handler.pyx", line 48, in cefpython_py37.V8FunctionHandler_Execute
  File "/media/feodoritiy/HDD/CODE/VS_C+/fti/Cursach/client/logic/login.py", line 10, in login
    'password': password,
  File "/media/feodoritiy/HDD/CODE/VS_C+/fti/Cursach/client/storage.py", line 37, in load
    res = requests.post(f'{SERVER}{path}', data)
  File "/usr/lib/python3/dist-packages/requests/api.py", line 116, in post
    return request('post', url, data=data, json=json, **kwargs)
  File "/usr/lib/python3/dist-packages/requests/api.py", line 60, in request
    return session.request(method=method, url=url, **kwargs)
  File "/usr/lib/python3/dist-packages/requests/sessions.py", line 533, in request
    resp = self.send(prep, **send_kwargs)
  File "/usr/lib/python3/dist-packages/requests/sessions.py", line 646, in send
    r = adapter.send(request, **kwargs)
  File "/usr/lib/python3/dist-packages/requests/adapters.py", line 516, in send
    raise ConnectionError(e, request=request)
requests.exceptions.ConnectionError: HTTPConnectionPool(host='127.0.0.1', port=1234): Max retries exceeded with url: /login (Caused by NewConnectionError('<urllib3.connection.HTTPConnection object at 0x7fa7084d8c50>: Failed to establish a new connection: [Errno 111] Connection refused'))


[2021-04-18 00:59:38] Traceback (most recent call last):
  File "/usr/lib/python3/dist-packages/urllib3/connectionpool.py", line 672, in urlopen
    chunked=chunked,
  File "/usr/lib/python3/dist-packages/urllib3/connectionpool.py", line 421, in _make_request
    six.raise_from(e, None)
  File "<string>", line 3, in raise_from
  File "/usr/lib/python3/dist-packages/urllib3/connectionpool.py", line 416, in _make_request
    httplib_response = conn.getresponse()
  File "/usr/lib/python3.7/http/client.py", line 1369, in getresponse
    response.begin()
  File "/usr/lib/python3.7/http/client.py", line 310, in begin
    version, status, reason = self._read_status()
  File "/usr/lib/python3.7/http/client.py", line 279, in _read_status
    raise RemoteDisconnected("Remote end closed connection without"
http.client.RemoteDisconnected: Remote end closed connection without response

During handling of the above exception, another exception occurred:

Traceback (most recent call last):
  File "/usr/lib/python3/dist-packages/requests/adapters.py", line 449, in send
    timeout=timeout
  File "/usr/lib/python3/dist-packages/urllib3/connectionpool.py", line 720, in urlopen
    method, url, error=e, _pool=self, _stacktrace=sys.exc_info()[2]
  File "/usr/lib/python3/dist-packages/urllib3/util/retry.py", line 400, in increment
    raise six.reraise(type(error), error, _stacktrace)
  File "/usr/lib/python3/dist-packages/six.py", line 702, in reraise
    raise value.with_traceback(tb)
  File "/usr/lib/python3/dist-packages/urllib3/connectionpool.py", line 672, in urlopen
    chunked=chunked,
  File "/usr/lib/python3/dist-packages/urllib3/connectionpool.py", line 421, in _make_request
    six.raise_from(e, None)
  File "<string>", line 3, in raise_from
  File "/usr/lib/python3/dist-packages/urllib3/connectionpool.py", line 416, in _make_request
    httplib_response = conn.getresponse()
  File "/usr/lib/python3.7/http/client.py", line 1369, in getresponse
    response.begin()
  File "/usr/lib/python3.7/http/client.py", line 310, in begin
    version, status, reason = self._read_status()
  File "/usr/lib/python3.7/http/client.py", line 279, in _read_status
    raise RemoteDisconnected("Remote end closed connection without"
urllib3.exceptions.ProtocolError: ('Connection aborted.', RemoteDisconnected('Remote end closed connection without response'))

During handling of the above exception, another exception occurred:

Traceback (most recent call last):
  File "v8function_handler.pyx", line 48, in cefpython_py37.V8FunctionHandler_Execute
  File "/media/feodoritiy/HDD/CODE/VS_C+/fti/Cursach/client/logic/game.py", line 120, in send_step
    'skin': order_data['skin'],
  File "/media/feodoritiy/HDD/CODE/VS_C+/fti/Cursach/client/storage.py", line 54, in gameload
    return this.load('/game', final_data)
  File "/media/feodoritiy/HDD/CODE/VS_C+/fti/Cursach/client/storage.py", line 37, in load
    res = requests.post(f'{SERVER}{path}', data)
  File "/usr/lib/python3/dist-packages/requests/api.py", line 116, in post
    return request('post', url, data=data, json=json, **kwargs)
  File "/usr/lib/python3/dist-packages/requests/api.py", line 60, in request
    return session.request(method=method, url=url, **kwargs)
  File "/usr/lib/python3/dist-packages/requests/sessions.py", line 533, in request
    resp = self.send(prep, **send_kwargs)
  File "/usr/lib/python3/dist-packages/requests/sessions.py", line 646, in send
    r = adapter.send(request, **kwargs)
  File "/usr/lib/python3/dist-packages/requests/adapters.py", line 498, in send
    raise ConnectionError(err, request=request)
requests.exceptions.ConnectionError: ('Connection aborted.', RemoteDisconnected('Remote end closed connection without response'))


[2021-04-18 01:37:47] Traceback (most recent call last):
  File "v8function_handler.pyx", line 48, in cefpython_py37.V8FunctionHandler_Execute
  File "/media/feodoritiy/HDD/CODE/VS_C+/fti/Cursach/client/logic/shop.py", line 55, in shop_buy
    if res['status'] == 'OK':
TypeError: 'Response' object is not subscriptable


[2021-04-18 01:51:38] Traceback (most recent call last):
  File "v8function_handler.pyx", line 48, in cefpython_py37.V8FunctionHandler_Execute
  File "/media/feodoritiy/HDD/CODE/VS_C+/fti/Cursach/client/logic/shop.py", line 55, in shop_buy
    if res['status'] == 'OK':
TypeError: 'Response' object is not subscriptable


[2021-04-18 01:53:10] Traceback (most recent call last):
  File "v8function_handler.pyx", line 48, in cefpython_py37.V8FunctionHandler_Execute
  File "/media/feodoritiy/HDD/CODE/VS_C+/fti/Cursach/client/logic/shop.py", line 55, in shop_buy
    if res['status'] == 'OK':
TypeError: 'Response' object is not subscriptable


[2021-04-18 01:58:26] Traceback (most recent call last):
  File "v8function_handler.pyx", line 48, in cefpython_py37.V8FunctionHandler_Execute
  File "/media/feodoritiy/HDD/CODE/VS_C+/fti/Cursach/client/logic/shop.py", line 55, in shop_buy
    if res['status'] == 'OK':
TypeError: 'Response' object is not subscriptable


[2021-04-18 02:00:28] Traceback (most recent call last):
  File "v8function_handler.pyx", line 48, in cefpython_py37.V8FunctionHandler_Execute
  File "/media/feodoritiy/HDD/CODE/VS_C+/fti/Cursach/client/logic/shop.py", line 55, in shop_buy
    if res['status'] == 'OK':
TypeError: 'Response' object is not subscriptable


[2021-04-18 02:02:03] Traceback (most recent call last):
  File "v8function_handler.pyx", line 48, in cefpython_py37.V8FunctionHandler_Execute
  File "/media/feodoritiy/HDD/CODE/VS_C+/fti/Cursach/client/logic/shop.py", line 55, in shop_buy
    if res['status'] == 'OK':
TypeError: 'Response' object is not subscriptable


[2021-04-18 02:04:39] Traceback (most recent call last):
  File "v8function_handler.pyx", line 48, in cefpython_py37.V8FunctionHandler_Execute
  File "/media/feodoritiy/HDD/CODE/VS_C+/fti/Cursach/client/logic/shop.py", line 55, in shop_buy
    if res['status'] == 'OK':
TypeError: 'Response' object is not subscriptable


[2021-04-18 02:07:33] Traceback (most recent call last):
  File "v8function_handler.pyx", line 48, in cefpython_py37.V8FunctionHandler_Execute
  File "/media/feodoritiy/HDD/CODE/VS_C+/fti/Cursach/client/logic/shop.py", line 55, in shop_buy
    if res['status'] == 'OK':
TypeError: 'Response' object is not subscriptable


[2021-04-18 02:09:53] Traceback (most recent call last):
  File "v8function_handler.pyx", line 48, in cefpython_py37.V8FunctionHandler_Execute
  File "/media/feodoritiy/HDD/CODE/VS_C+/fti/Cursach/client/logic/shop.py", line 55, in shop_buy
    if res['status'] == 'OK':
TypeError: 'Response' object is not subscriptable


[2021-04-18 02:15:59] Traceback (most recent call last):
  File "lifespan_handler.pyx", line 129, in cefpython_py37.LifespanHandler_OnBeforeClose
  File "/media/feodoritiy/HDD/CODE/VS_C+/fti/Cursach/client/browser.py", line 97, in OnBeforeClose
    storage.connection_process.terminate()
AttributeError: 'NoneType' object has no attribute 'terminate'


[2021-04-24 23:34:32] Traceback (most recent call last):
  File "v8function_handler.pyx", line 48, in cefpython_py37.V8FunctionHandler_Execute
  File "/media/feodoritiy/HDD/CODE/VS_C+/fti/Cursach/client/logic/login.py", line 15, in login
    if (res['status'] == 'OK'):
TypeError: 'Response' object is not subscriptable


[2021-04-24 23:38:42] Traceback (most recent call last):
  File "v8function_handler.pyx", line 48, in cefpython_py37.V8FunctionHandler_Execute
  File "/media/feodoritiy/HDD/SWAP/ФТИ/1курс/Программирование/Подъюбкин_Курсач_Флиртович/Тимур_Дубинский/client/logic/create_game.py", line 12, in create_game
    if res['status'] == 'OK':
TypeError: 'Response' object is not subscriptable


[2021-04-26 00:13:17] Traceback (most recent call last):
  File "lifespan_handler.pyx", line 129, in cefpython_py37.LifespanHandler_OnBeforeClose
  File "/media/feodoritiy/HDD/SWAP/ФТИ/1курс/Программирование/Подъюбкин_Курсач_Флиртович/Тимур_Дубинский/client/browser.py", line 97, in OnBeforeClose
    storage.connection_process.terminate()
AttributeError: 'NoneType' object has no attribute 'terminate'


[2021-04-26 00:15:06] Traceback (most recent call last):
  File "lifespan_handler.pyx", line 129, in cefpython_py37.LifespanHandler_OnBeforeClose
  File "/media/feodoritiy/HDD/SWAP/ФТИ/1курс/Программирование/Подъюбкин_Курсач_Флиртович/Тимур_Дубинский/client/browser.py", line 97, in OnBeforeClose
    storage.connection_process.terminate()
AttributeError: 'NoneType' object has no attribute 'terminate'


[2021-04-26 00:17:02] Traceback (most recent call last):
  File "lifespan_handler.pyx", line 129, in cefpython_py37.LifespanHandler_OnBeforeClose
  File "/media/feodoritiy/HDD/SWAP/ФТИ/1курс/Программирование/Подъюбкин_Курсач_Флиртович/Тимур_Дубинский/client/browser.py", line 97, in OnBeforeClose
    storage.connection_process.terminate()
AttributeError: 'NoneType' object has no attribute 'terminate'


[2021-04-26 00:17:38] Traceback (most recent call last):
  File "lifespan_handler.pyx", line 129, in cefpython_py37.LifespanHandler_OnBeforeClose
  File "/media/feodoritiy/HDD/SWAP/ФТИ/1курс/Программирование/Подъюбкин_Курсач_Флиртович/Тимур_Дубинский/client/browser.py", line 97, in OnBeforeClose
    storage.connection_process.terminate()
AttributeError: 'NoneType' object has no attribute 'terminate'


[2021-04-26 00:32:22] Traceback (most recent call last):
  File "lifespan_handler.pyx", line 129, in cefpython_py37.LifespanHandler_OnBeforeClose
  File "/media/feodoritiy/HDD/SWAP/ФТИ/1курс/Программирование/Подъюбкин_Курсач_Флиртович/Тимур_Дубинский/client/browser.py", line 97, in OnBeforeClose
    storage.connection_process.terminate()
AttributeError: 'NoneType' object has no attribute 'terminate'


[2021-04-26 10:22:49] Traceback (most recent call last):
  File "lifespan_handler.pyx", line 129, in cefpython_py37.LifespanHandler_OnBeforeClose
  File "/media/feodoritiy/HDD/SWAP/ФТИ/1курс/Программирование/Подъюбкин_Курсач_Флиртович/Тимур_Дубинский/client/browser.py", line 97, in OnBeforeClose
    storage.connection_process.terminate()
AttributeError: 'NoneType' object has no attribute 'terminate'


[2021-04-26 10:31:28] Traceback (most recent call last):
  File "lifespan_handler.pyx", line 129, in cefpython_py37.LifespanHandler_OnBeforeClose
  File "/media/feodoritiy/HDD/SWAP/ФТИ/1курс/Программирование/Подъюбкин_Курсач_Флиртович/Тимур_Дубинский/client/browser.py", line 97, in OnBeforeClose
    storage.connection_process.terminate()
AttributeError: 'NoneType' object has no attribute 'terminate'


[2021-04-26 10:43:31] Traceback (most recent call last):
  File "lifespan_handler.pyx", line 129, in cefpython_py37.LifespanHandler_OnBeforeClose
  File "/media/feodoritiy/HDD/SWAP/ФТИ/1курс/Программирование/Подъюбкин_Курсач_Флиртович/Тимур_Дубинский/client/browser.py", line 97, in OnBeforeClose
    storage.connection_process.terminate()
AttributeError: 'NoneType' object has no attribute 'terminate'


[2021-04-26 10:45:25] Traceback (most recent call last):
  File "lifespan_handler.pyx", line 129, in cefpython_py37.LifespanHandler_OnBeforeClose
  File "/media/feodoritiy/HDD/SWAP/ФТИ/1курс/Программирование/Подъюбкин_Курсач_Флиртович/Тимур_Дубинский/client/browser.py", line 97, in OnBeforeClose
    storage.connection_process.terminate()
AttributeError: 'NoneType' object has no attribute 'terminate'


[2021-04-26 10:45:45] Traceback (most recent call last):
  File "lifespan_handler.pyx", line 129, in cefpython_py37.LifespanHandler_OnBeforeClose
  File "/media/feodoritiy/HDD/SWAP/ФТИ/1курс/Программирование/Подъюбкин_Курсач_Флиртович/Тимур_Дубинский/client/browser.py", line 97, in OnBeforeClose
    storage.connection_process.terminate()
AttributeError: 'NoneType' object has no attribute 'terminate'


[2021-04-26 11:00:18] Traceback (most recent call last):
  File "lifespan_handler.pyx", line 129, in cefpython_py37.LifespanHandler_OnBeforeClose
  File "/media/feodoritiy/HDD/SWAP/ФТИ/1курс/Программирование/Подъюбкин_Курсач_Флиртович/Тимур_Дубинский/client/browser.py", line 97, in OnBeforeClose
    storage.connection_process.terminate()
AttributeError: 'NoneType' object has no attribute 'terminate'


[2021-04-26 11:01:31] Traceback (most recent call last):
  File "lifespan_handler.pyx", line 129, in cefpython_py37.LifespanHandler_OnBeforeClose
  File "/media/feodoritiy/HDD/SWAP/ФТИ/1курс/Программирование/Подъюбкин_Курсач_Флиртович/Тимур_Дубинский/client/browser.py", line 97, in OnBeforeClose
    storage.connection_process.terminate()
AttributeError: 'NoneType' object has no attribute 'terminate'


[2021-04-26 11:02:27] Traceback (most recent call last):
  File "lifespan_handler.pyx", line 129, in cefpython_py37.LifespanHandler_OnBeforeClose
  File "/media/feodoritiy/HDD/SWAP/ФТИ/1курс/Программирование/Подъюбкин_Курсач_Флиртович/Тимур_Дубинский/client/browser.py", line 97, in OnBeforeClose
    storage.connection_process.terminate()
AttributeError: 'NoneType' object has no attribute 'terminate'


[2021-04-26 11:05:32] Traceback (most recent call last):
  File "lifespan_handler.pyx", line 129, in cefpython_py37.LifespanHandler_OnBeforeClose
  File "/media/feodoritiy/HDD/SWAP/ФТИ/1курс/Программирование/Подъюбкин_Курсач_Флиртович/Тимур_Дубинский/client/browser.py", line 97, in OnBeforeClose
    storage.connection_process.terminate()
AttributeError: 'NoneType' object has no attribute 'terminate'


[2021-04-26 11:06:18] Traceback (most recent call last):
  File "lifespan_handler.pyx", line 129, in cefpython_py37.LifespanHandler_OnBeforeClose
  File "/media/feodoritiy/HDD/SWAP/ФТИ/1курс/Программирование/Подъюбкин_Курсач_Флиртович/Тимур_Дубинский/client/browser.py", line 97, in OnBeforeClose
    storage.connection_process.terminate()
AttributeError: 'NoneType' object has no attribute 'terminate'


[2021-04-26 11:11:29] Traceback (most recent call last):
  File "lifespan_handler.pyx", line 129, in cefpython_py37.LifespanHandler_OnBeforeClose
  File "/media/feodoritiy/HDD/SWAP/ФТИ/1курс/Программирование/Подъюбкин_Курсач_Флиртович/Тимур_Дубинский/client/browser.py", line 97, in OnBeforeClose
    storage.connection_process.terminate()
AttributeError: 'NoneType' object has no attribute 'terminate'


[2021-04-26 11:12:08] Traceback (most recent call last):
  File "lifespan_handler.pyx", line 129, in cefpython_py37.LifespanHandler_OnBeforeClose
  File "/media/feodoritiy/HDD/SWAP/ФТИ/1курс/Программирование/Подъюбкин_Курсач_Флиртович/Тимур_Дубинский/client/browser.py", line 97, in OnBeforeClose
    storage.connection_process.terminate()
AttributeError: 'NoneType' object has no attribute 'terminate'


[2021-04-26 11:13:21] Traceback (most recent call last):
  File "lifespan_handler.pyx", line 129, in cefpython_py37.LifespanHandler_OnBeforeClose
  File "/media/feodoritiy/HDD/SWAP/ФТИ/1курс/Программирование/Подъюбкин_Курсач_Флиртович/Тимур_Дубинский/client/browser.py", line 97, in OnBeforeClose
    storage.connection_process.terminate()
AttributeError: 'NoneType' object has no attribute 'terminate'


[2021-04-26 11:14:02] Traceback (most recent call last):
  File "lifespan_handler.pyx", line 129, in cefpython_py37.LifespanHandler_OnBeforeClose
  File "/media/feodoritiy/HDD/SWAP/ФТИ/1курс/Программирование/Подъюбкин_Курсач_Флиртович/Тимур_Дубинский/client/browser.py", line 97, in OnBeforeClose
    storage.connection_process.terminate()
AttributeError: 'NoneType' object has no attribute 'terminate'


[2021-04-27 17:09:04] Traceback (most recent call last):
  File "v8function_handler.pyx", line 48, in cefpython_py37.V8FunctionHandler_Execute
  File "/media/feodoritiy/HDD/SWAP/ФТИ/1курс/Программирование/Подъюбкин_Курсач_Флиртович/Тимур_Дубинский/client/logic/create_game.py", line 10, in create_game
    if res['status'] == 'OK':
TypeError: 'Response' object is not subscriptable


[2021-04-27 17:11:09] Traceback (most recent call last):
  File "v8function_handler.pyx", line 48, in cefpython_py37.V8FunctionHandler_Execute
  File "/media/feodoritiy/HDD/SWAP/ФТИ/1курс/Программирование/Подъюбкин_Курсач_Флиртович/Тимур_Дубинский/client/logic/create_game.py", line 21, in create_game
    if res['status'] == 'OK':
TypeError: 'Response' object is not subscriptable


[2021-04-27 17:12:15] Traceback (most recent call last):
  File "v8function_handler.pyx", line 48, in cefpython_py37.V8FunctionHandler_Execute
  File "/media/feodoritiy/HDD/SWAP/ФТИ/1курс/Программирование/Подъюбкин_Курсач_Флиртович/Тимур_Дубинский/client/logic/create_game.py", line 10, in create_game
    if res['status'] == 'OK':
TypeError: 'Response' object is not subscriptable


[2021-04-27 17:14:01] Traceback (most recent call last):
  File "v8function_handler.pyx", line 48, in cefpython_py37.V8FunctionHandler_Execute
  File "/media/feodoritiy/HDD/SWAP/ФТИ/1курс/Программирование/Подъюбкин_Курсач_Флиртович/Тимур_Дубинский/client/logic/create_game.py", line 10, in create_game
    if res['status'] == 'OK':
TypeError: 'Response' object is not subscriptable


[2021-04-27 17:28:37] Traceback (most recent call last):
  File "v8function_handler.pyx", line 48, in cefpython_py37.V8FunctionHandler_Execute
  File "/media/feodoritiy/HDD/SWAP/ФТИ/1курс/Программирование/Подъюбкин_Курсач_Флиртович/Тимур_Дубинский/client/logic/create_game.py", line 10, in create_game
    if res['status'] == 'OK':
TypeError: 'Response' object is not subscriptable


[2021-04-27 17:31:44] Traceback (most recent call last):
  File "v8function_handler.pyx", line 48, in cefpython_py37.V8FunctionHandler_Execute
  File "/media/feodoritiy/HDD/SWAP/ФТИ/1курс/Программирование/Подъюбкин_Курсач_Флиртович/Тимур_Дубинский/client/logic/create_game.py", line 10, in create_game
    if res['status'] == 'OK':
TypeError: 'Response' object is not subscriptable


[2021-04-27 17:37:41] Traceback (most recent call last):
  File "v8function_handler.pyx", line 48, in cefpython_py37.V8FunctionHandler_Execute
  File "/media/feodoritiy/HDD/SWAP/ФТИ/1курс/Программирование/Подъюбкин_Курсач_Флиртович/Тимур_Дубинский/client/logic/create_game.py", line 10, in create_game
    if res['status'] == 'OK':
TypeError: 'Response' object is not subscriptable


[2021-04-27 17:38:51] Traceback (most recent call last):
  File "v8function_handler.pyx", line 48, in cefpython_py37.V8FunctionHandler_Execute
  File "/media/feodoritiy/HDD/SWAP/ФТИ/1курс/Программирование/Подъюбкин_Курсач_Флиртович/Тимур_Дубинский/client/logic/create_game.py", line 12, in create_game
    print('Create Game: SID =', res['sid'])
KeyError: 'sid'


[2021-04-27 17:39:24] Traceback (most recent call last):
  File "v8function_handler.pyx", line 48, in cefpython_py37.V8FunctionHandler_Execute
  File "/media/feodoritiy/HDD/SWAP/ФТИ/1курс/Программирование/Подъюбкин_Курсач_Флиртович/Тимур_Дубинский/client/logic/game.py", line 74, in get_game_sid
    callback.Call(storage.sid)
AttributeError: module 'storage' has no attribute 'sid'


[2021-04-27 18:10:05] Traceback (most recent call last):
  File "v8function_handler.pyx", line 48, in cefpython_py37.V8FunctionHandler_Execute
  File "/media/feodoritiy/HDD/SWAP/ФТИ/1курс/Программирование/Подъюбкин_Курсач_Флиртович/Тимур_Дубинский/client/logic/game.py", line 82, in get_skin
    callback.Call(res['skin'])
TypeError: 'Response' object is not subscriptable


[2021-04-27 18:37:15] Traceback (most recent call last):
  File "lifespan_handler.pyx", line 129, in cefpython_py37.LifespanHandler_OnBeforeClose
  File "/media/feodoritiy/HDD/SWAP/ФТИ/1курс/Программирование/Подъюбкин_Курсач_Флиртович/Тимур_Дубинский/client/browser.py", line 97, in OnBeforeClose
    storage.connection_process.terminate()
AttributeError: 'NoneType' object has no attribute 'terminate'


[2021-04-28 21:30:20] Traceback (most recent call last):
  File "v8function_handler.pyx", line 48, in cefpython_py37.V8FunctionHandler_Execute
  File "/media/feodoritiy/HDD/SWAP/ФТИ/1курс/Программирование/Подъюбкин_Курсач_Флиртович/Тимур_Дубинский/client/logic/game.py", line 82, in get_skin
    callback.Call(res['skin'])
TypeError: 'Response' object is not subscriptable


[2021-04-29 20:19:29] Traceback (most recent call last):
  File "/usr/lib/python3/dist-packages/urllib3/connection.py", line 160, in _new_conn
    (self._dns_host, self.port), self.timeout, **extra_kw
  File "/usr/lib/python3/dist-packages/urllib3/util/connection.py", line 84, in create_connection
    raise err
  File "/usr/lib/python3/dist-packages/urllib3/util/connection.py", line 74, in create_connection
    sock.connect(sa)
ConnectionRefusedError: [Errno 111] Connection refused

During handling of the above exception, another exception occurred:

Traceback (most recent call last):
  File "/usr/lib/python3/dist-packages/urllib3/connectionpool.py", line 672, in urlopen
    chunked=chunked,
  File "/usr/lib/python3/dist-packages/urllib3/connectionpool.py", line 387, in _make_request
    conn.request(method, url, **httplib_request_kw)
  File "/usr/lib/python3.7/http/client.py", line 1277, in request
    self._send_request(method, url, body, headers, encode_chunked)
  File "/usr/lib/python3.7/http/client.py", line 1323, in _send_request
    self.endheaders(body, encode_chunked=encode_chunked)
  File "/usr/lib/python3.7/http/client.py", line 1272, in endheaders
    self._send_output(message_body, encode_chunked=encode_chunked)
  File "/usr/lib/python3.7/http/client.py", line 1032, in _send_output
    self.send(msg)
  File "/usr/lib/python3.7/http/client.py", line 972, in send
    self.connect()
  File "/usr/lib/python3/dist-packages/urllib3/connection.py", line 187, in connect
    conn = self._new_conn()
  File "/usr/lib/python3/dist-packages/urllib3/connection.py", line 172, in _new_conn
    self, "Failed to establish a new connection: %s" % e
urllib3.exceptions.NewConnectionError: <urllib3.connection.HTTPConnection object at 0x7fb3e434e190>: Failed to establish a new connection: [Errno 111] Connection refused

During handling of the above exception, another exception occurred:

Traceback (most recent call last):
  File "/usr/lib/python3/dist-packages/requests/adapters.py", line 449, in send
    timeout=timeout
  File "/usr/lib/python3/dist-packages/urllib3/connectionpool.py", line 720, in urlopen
    method, url, error=e, _pool=self, _stacktrace=sys.exc_info()[2]
  File "/usr/lib/python3/dist-packages/urllib3/util/retry.py", line 436, in increment
    raise MaxRetryError(_pool, url, error or ResponseError(cause))
urllib3.exceptions.MaxRetryError: HTTPConnectionPool(host='127.0.0.1', port=1234): Max retries exceeded with url: /game (Caused by NewConnectionError('<urllib3.connection.HTTPConnection object at 0x7fb3e434e190>: Failed to establish a new connection: [Errno 111] Connection refused'))

During handling of the above exception, another exception occurred:

Traceback (most recent call last):
  File "v8function_handler.pyx", line 48, in cefpython_py37.V8FunctionHandler_Execute
  File "/media/feodoritiy/HDD/SWAP/ФТИ/1курс/Программирование/Подъюбкин_Курсач_Флиртович/Тимур_Дубинский/client/logic/game.py", line 87, in get_ready_count
    res = storage.gameload('get-ready-count', {})
  File "/media/feodoritiy/HDD/SWAP/ФТИ/1курс/Программирование/Подъюбкин_Курсач_Флиртович/Тимур_Дубинский/client/storage.py", line 54, in gameload
    return this.load('/game', final_data)
  File "/media/feodoritiy/HDD/SWAP/ФТИ/1курс/Программирование/Подъюбкин_Курсач_Флиртович/Тимур_Дубинский/client/storage.py", line 37, in load
    res = requests.post(f'{SERVER}{path}', data)
  File "/usr/lib/python3/dist-packages/requests/api.py", line 116, in post
    return request('post', url, data=data, json=json, **kwargs)
  File "/usr/lib/python3/dist-packages/requests/api.py", line 60, in request
    return session.request(method=method, url=url, **kwargs)
  File "/usr/lib/python3/dist-packages/requests/sessions.py", line 533, in request
    resp = self.send(prep, **send_kwargs)
  File "/usr/lib/python3/dist-packages/requests/sessions.py", line 646, in send
    r = adapter.send(request, **kwargs)
  File "/usr/lib/python3/dist-packages/requests/adapters.py", line 516, in send
    raise ConnectionError(e, request=request)
requests.exceptions.ConnectionError: HTTPConnectionPool(host='127.0.0.1', port=1234): Max retries exceeded with url: /game (Caused by NewConnectionError('<urllib3.connection.HTTPConnection object at 0x7fb3e434e190>: Failed to establish a new connection: [Errno 111] Connection refused'))


[2021-04-29 20:19:45] Traceback (most recent call last):
  File "/usr/lib/python3/dist-packages/urllib3/connection.py", line 160, in _new_conn
    (self._dns_host, self.port), self.timeout, **extra_kw
  File "/usr/lib/python3/dist-packages/urllib3/util/connection.py", line 84, in create_connection
    raise err
  File "/usr/lib/python3/dist-packages/urllib3/util/connection.py", line 74, in create_connection
    sock.connect(sa)
ConnectionRefusedError: [Errno 111] Connection refused

During handling of the above exception, another exception occurred:

Traceback (most recent call last):
  File "/usr/lib/python3/dist-packages/urllib3/connectionpool.py", line 672, in urlopen
    chunked=chunked,
  File "/usr/lib/python3/dist-packages/urllib3/connectionpool.py", line 387, in _make_request
    conn.request(method, url, **httplib_request_kw)
  File "/usr/lib/python3.7/http/client.py", line 1277, in request
    self._send_request(method, url, body, headers, encode_chunked)
  File "/usr/lib/python3.7/http/client.py", line 1323, in _send_request
    self.endheaders(body, encode_chunked=encode_chunked)
  File "/usr/lib/python3.7/http/client.py", line 1272, in endheaders
    self._send_output(message_body, encode_chunked=encode_chunked)
  File "/usr/lib/python3.7/http/client.py", line 1032, in _send_output
    self.send(msg)
  File "/usr/lib/python3.7/http/client.py", line 972, in send
    self.connect()
  File "/usr/lib/python3/dist-packages/urllib3/connection.py", line 187, in connect
    conn = self._new_conn()
  File "/usr/lib/python3/dist-packages/urllib3/connection.py", line 172, in _new_conn
    self, "Failed to establish a new connection: %s" % e
urllib3.exceptions.NewConnectionError: <urllib3.connection.HTTPConnection object at 0x7f11a06a5250>: Failed to establish a new connection: [Errno 111] Connection refused

During handling of the above exception, another exception occurred:

Traceback (most recent call last):
  File "/usr/lib/python3/dist-packages/requests/adapters.py", line 449, in send
    timeout=timeout
  File "/usr/lib/python3/dist-packages/urllib3/connectionpool.py", line 720, in urlopen
    method, url, error=e, _pool=self, _stacktrace=sys.exc_info()[2]
  File "/usr/lib/python3/dist-packages/urllib3/util/retry.py", line 436, in increment
    raise MaxRetryError(_pool, url, error or ResponseError(cause))
urllib3.exceptions.MaxRetryError: HTTPConnectionPool(host='127.0.0.1', port=1234): Max retries exceeded with url: /create-game (Caused by NewConnectionError('<urllib3.connection.HTTPConnection object at 0x7f11a06a5250>: Failed to establish a new connection: [Errno 111] Connection refused'))

During handling of the above exception, another exception occurred:

Traceback (most recent call last):
  File "v8function_handler.pyx", line 48, in cefpython_py37.V8FunctionHandler_Execute
  File "/media/feodoritiy/HDD/SWAP/ФТИ/1курс/Программирование/Подъюбкин_Курсач_Флиртович/Тимур_Дубинский/client/logic/create_game.py", line 8, in create_game
    res = storage.load('/create-game', {})
  File "/media/feodoritiy/HDD/SWAP/ФТИ/1курс/Программирование/Подъюбкин_Курсач_Флиртович/Тимур_Дубинский/client/storage.py", line 37, in load
    res = requests.post(f'{SERVER}{path}', data)
  File "/usr/lib/python3/dist-packages/requests/api.py", line 116, in post
    return request('post', url, data=data, json=json, **kwargs)
  File "/usr/lib/python3/dist-packages/requests/api.py", line 60, in request
    return session.request(method=method, url=url, **kwargs)
  File "/usr/lib/python3/dist-packages/requests/sessions.py", line 533, in request
    resp = self.send(prep, **send_kwargs)
  File "/usr/lib/python3/dist-packages/requests/sessions.py", line 646, in send
    r = adapter.send(request, **kwargs)
  File "/usr/lib/python3/dist-packages/requests/adapters.py", line 516, in send
    raise ConnectionError(e, request=request)
requests.exceptions.ConnectionError: HTTPConnectionPool(host='127.0.0.1', port=1234): Max retries exceeded with url: /create-game (Caused by NewConnectionError('<urllib3.connection.HTTPConnection object at 0x7f11a06a5250>: Failed to establish a new connection: [Errno 111] Connection refused'))


[2021-04-29 21:12:02] Traceback (most recent call last):
  File "lifespan_handler.pyx", line 129, in cefpython_py37.LifespanHandler_OnBeforeClose
  File "/media/feodoritiy/HDD/SWAP/ФТИ/1курс/Программирование/Подъюбкин_Курсач_Флиртович/Тимур_Дубинский/client/browser.py", line 97, in OnBeforeClose
    storage.connection_process.terminate()
AttributeError: 'NoneType' object has no attribute 'terminate'


[2021-04-29 21:32:32] Traceback (most recent call last):
  File "lifespan_handler.pyx", line 129, in cefpython_py37.LifespanHandler_OnBeforeClose
  File "/media/feodoritiy/HDD/SWAP/ФТИ/1курс/Программирование/Подъюбкин_Курсач_Флиртович/Тимур_Дубинский/client/browser.py", line 97, in OnBeforeClose
    storage.connection_process.terminate()
AttributeError: 'NoneType' object has no attribute 'terminate'


[2021-04-29 21:46:56] Traceback (most recent call last):
  File "lifespan_handler.pyx", line 129, in cefpython_py37.LifespanHandler_OnBeforeClose
  File "/media/feodoritiy/HDD/SWAP/ФТИ/1курс/Программирование/Подъюбкин_Курсач_Флиртович/Тимур_Дубинский/client/browser.py", line 97, in OnBeforeClose
    storage.connection_process.terminate()
AttributeError: 'NoneType' object has no attribute 'terminate'


[2021-04-29 23:42:07] Traceback (most recent call last):
  File "lifespan_handler.pyx", line 129, in cefpython_py37.LifespanHandler_OnBeforeClose
  File "/media/feodoritiy/HDD/SWAP/ФТИ/1курс/Программирование/Подъюбкин_Курсач_Флиртович/Тимур_Дубинский/client/browser.py", line 97, in OnBeforeClose
    storage.connection_process.terminate()
AttributeError: 'NoneType' object has no attribute 'terminate'


[2021-04-30 00:53:50] Traceback (most recent call last):
  File "lifespan_handler.pyx", line 129, in cefpython_py37.LifespanHandler_OnBeforeClose
  File "/media/feodoritiy/HDD/SWAP/ФТИ/1курс/Программирование/Подъюбкин_Курсач_Флиртович/Тимур_Дубинский/client/browser.py", line 97, in OnBeforeClose
    storage.connection_process.terminate()
AttributeError: 'NoneType' object has no attribute 'terminate'

